Workbook
Name NativeTimeline_Order_Date: #N/A
Name Slicer_on_time: #N/A
Name Slicer_order_status: #N/A
Name Slicer_Rain_mode_updated: #N/A

Sheet Swiggy Orders
A1: order_id | B1: is_coupon_applied | C1: coupon_applied | D1: offers_data | E1: order_time | F1: confirmed_time | G1: customer_id | H1: order_status | I1: delivery_boy.name | J1: restaurant_id | K1: restaurant_name | L1: restaurant_address | M1: restaurant_locality | N1: restaurant_city_name | O1: delivery_time_in_seconds | P1: order_total | Q1: order_total_with_tip | R1: net_total | S1: item_total | T1: free_delivery_discount_hit | U1: restaurant_order_rating | V1: restaurant_lat_lng | W1: restaurant_customer_distance | X1: coupon_code | Y1: order_payment_method | Z1: restaurant_area_name | AA1: on_time | AB1: rain_mode | AC1: Coupon_Code_Updated | AD1: restaurant_name_updated | AE1: restaurant_area_name_updated | AF1: Discount | AG1: Order_Date | AH1: Time | AI1: Weekday | AJ1: Day_Seg | AK1: Rain_mode_updated | AQ1: Hrs | AR1: Segments
A2: 175244332362622 | B2: TRUE | C2: SWIGGYIT | D2: [{"id":"7740ff94-cc8f-41cf-b6ec-d4c97cbd0060","super_type":"SUPERTYPE_UNSPECIFIED","total_offer_discount":120,"discount_share":{"swiggy_discount":67.2,"store_discount":52.8,"alliance_discount":0},"discount_type":"PERCENTAGE","description":"60% off","fixed_charges":{"gp":{"id":"","final_price":0}}}] | E2: 2024-05-21 12:28:52 | F2: 2024-05-21 12:29:13 | G2: 21191609 | H2: Delivered | I2: NARREDDY NAGESWARA REDDY | J2: 434304 | K2: Paris Panini - Gourmet Sandwiches & Wraps | L2: No.690/A, 14th Main, 100ft Road, JP Nagar 2nd Phase, Bangalore 560078. | M2: JP Nagar | N2: Bangalore | O2: 1587 | P2: 146 | Q2: 146 | R2: 146 | S2: 225 | T2: 43 | U2: 0 | V2: 12.90649867,77.59165435 | W2: 2.2 | X2: SWIGGYIT | Y2: UPICollect | Z2: JP Nagar | AA2: FALSE | AB2: 0 | AC2: =IF(X2="","No Coupon Applied",X2) -> SWIGGYIT | AD2: =VLOOKUP(K2,'restaurant name correction'!$A$1:$B$44,2,0) -> Paris Panini | AE2: =VLOOKUP(Z2,restaurant_area_correction!$A$1:$B$18,2,0) -> JP Nagar | AF2: =VALUE(IFERROR(MID(D2,FIND(":",D2,FIND("total_offer_discount",D2))+1,FIND(",",D2,FIND("total_offer_discount",D2)) - FIND(":",D2,FIND("total_offer_discount",D2))-1),0)) -> 120 | AG2: =DATEVALUE(E2) -> 45433 | AH2: =TIMEVALUE(E2) -> 0.5200463 | AI2: =TEXT(AG2,"dddd") -> Tuesday | AJ2: =VLOOKUP(HOUR(Orders[[#This Row],[Time]]),$AQ$1:$AR$7,2,1) -> Afternoon | AK2: =IF(Orders[[#This Row],[rain_mode]]=0,"Sunny","Rainy") -> Sunny | AQ2: 0 | AR2: Early Morning
A3: 175167017704058 | B3: FALSE | E3: 2024-05-20 15:00:17 | F3: 2024-05-20 15:00:38 | G3: 21191609 | H3: Delivered | I3: Kesavamoorthi | J3: 12804 | K3: Nandhana Palace | L3: JP nagar, 147, 24th Main Rd, R.K Colony, Marenahalli, 2nd Phase, J. P. Nagar, Bengaluru, Karnataka 560078 | M3: JP Nagar | N3: Bangalore | O3: 1853 | P3: 555 | Q3: 555 | R3: 555 | S3: 480 | T3: 41 | U3: 0 | V3: 12.914599,77.585509 | W3: 2.2 | Y3: UPICollect | Z3: JP Nagar | AA3: FALSE | AB3: 0 | AC3: =IF(X3="","No Coupon Applied",X3) -> No Coupon Applied | AD3: =VLOOKUP(K3,'restaurant name correction'!$A$1:$B$44,2,0) -> Nandhana Palace | AE3: =VLOOKUP(Z3,restaurant_area_correction!$A$1:$B$18,2,0) -> JP Nagar | AF3: =VALUE(IFERROR(MID(D3,FIND(":",D3,FIND("total_offer_discount",D3))+1,FIND(",",D3,FIND("total_offer_discount",D3)) - FIND(":",D3,FIND("total_offer_discount",D3))-1),0)) -> 0 | AG3: =DATEVALUE(E3) -> 45432 | AH3: =TIMEVALUE(E3) -> 0.62519676 | AI3: =TEXT(AG3,"dddd") -> Monday | AJ3: =VLOOKUP(HOUR(Orders[[#This Row],[Time]]),$AQ$1:$AR$7,2,1) -> Afternoon | AK3: =IF(Orders[[#This Row],[rain_mode]]=0,"Sunny","Rainy") -> Sunny | AQ3: 4 | AR3: Morning
A4: 175017114796029 | B4: TRUE | C4: MISSEDYOU | D4: [{"id":"c1399a7d-65f4-486a-ba3e-72a9d9c70cad","super_type":"SUPERTYPE_UNSPECIFIED","total_offer_discount":80,"discount_share":{"swiggy_discount":16,"store_discount":64,"alliance_discount":0},"discount_type":"PERCENTAGE","description":"40% off","fixed_charges":{"gp":{"id":"","final_price":0}}}] | E4: 2024-05-18 21:21:54 | F4: 2024-05-18 21:22:15 | G4: 21191609 | H4: Delivered | I4: Safiul Ansari | J4: 15250 | K4: The Ganache Factory - Cakes & Desserts | L4: #156, 43rd Cross, 8th Block, Next to Udupi Hub Resto, Jayanagar, Bangalore | M4: 8th Block | N4: Bangalore | O4: 1559 | P4: 382 | Q4: 382 | R4: 382 | S4: 400 | T4: 69 | U4: 0 | V4: 12.91835714,77.578127 | W4: 3.6 | X4: MISSEDYOU | Y4: UPICollect | Z4: Jayanagar | AA4: TRUE | AB4: 0 | AC4: =IF(X4="","No Coupon Applied",X4) -> MISSEDYOU | AD4: =VLOOKUP(K4,'restaurant name correction'!$A$1:$B$44,2,0) -> The Ganache Factory | AE4: =VLOOKUP(Z4,restaurant_area_correction!$A$1:$B$18,2,0) -> Jayanagar | AF4: =VALUE(IFERROR(MID(D4,FIND(":",D4,FIND("total_offer_discount",D4))+1,FIND(",",D4,FIND("total_offer_discount",D4)) - FIND(":",D4,FIND("total_offer_discount",D4))-1),0)) -> 80 | AG4: =DATEVALUE(E4) -> 45430 | AH4: =TIMEVALUE(E4) -> 0.89020833 | AI4: =TEXT(AG4,"dddd") -> Saturday | AJ4: =VLOOKUP(HOUR(Orders[[#This Row],[Time]]),$AQ$1:$AR$7,2,1) -> Night | AK4: =IF(Orders[[#This Row],[rain_mode]]=0,"Sunny","Rainy") -> Sunny | AQ4: 8 | AR4: Late Morning
A5: 174973046023416 | B5: TRUE | C5: SWIGGYIT | D5: [{"id":"28bf3ebb-4a69-4a92-88a4-f491a5f86e17","super_type":"SUPERTYPE_UNSPECIFIED","total_offer_discount":39.99,"discount_share":{"swiggy_discount":0,"store_discount":39.99,"alliance_discount":0},"discount_type":"PERCENTAGE","description":"10% off","fixed_charges":{"gp":{"id":"","final_price":0}}}] | E5: 2024-05-18 09:07:26 | F5: 2024-05-18 09:07:44 | G5: 21191609 | H5: Delivered | I5: Rama Krishna | J5: 630473 | K5: Rasayan | L5: 652,13th cross,29th main road BTM 2nd stage,560078, Bangalore Karnataka | M5: Health Bar | N5: Bangalore | O5: 3760 | P5: 421 | Q5: 421 | R5: 421 | S5: 415 | T5: 46 | U5: 0 | V5: 12.907799,77.613487 | W5: 2.5 | X5: SWIGGYIT | Y5: UPICollect | Z5: BTM 2nd Stage | AA5: FALSE | AB5: 0 | AC5: =IF(X5="","No Coupon Applied",X5) -> SWIGGYIT | AD5: =VLOOKUP(K5,'restaurant name correction'!$A$1:$B$44,2,0) -> Rasayan | AE5: =VLOOKUP(Z5,restaurant_area_correction!$A$1:$B$18,2,0) -> BTM | AF5: =VALUE(IFERROR(MID(D5,FIND(":",D5,FIND("total_offer_discount",D5))+1,FIND(",",D5,FIND("total_offer_discount",D5)) - FIND(":",D5,FIND("total_offer_discount",D5))-1),0)) -> 39.99 | AG5: =DATEVALUE(E5) -> 45430 | AH5: =TIMEVALUE(E5) -> 0.38016204 | AI5: =TEXT(AG5,"dddd") -> Saturday | AJ5: =VLOOKUP(HOUR(Orders[[#This Row],[Time]]),$AQ$1:$AR$7,2,1) -> Late Morning | AK5: =IF(Orders[[#This Row],[rain_mode]]=0,"Sunny","Rainy") -> Sunny | AQ5: 12 | AR5: Afternoon
A6: 174906705849277 | B6: TRUE | C6: DEALICIOUS | D6: [{"id":"91e6269d-640b-443e-a7d4-46089c0574f6","super_type":"SUPERTYPE_UNSPECIFIED","total_offer_discount":124.99,"discount_share":{"swiggy_discount":0,"store_discount":124.99,"alliance_discount":0},"discount_type":"FLAT","description":"FLAT125 off","fixed_charges":{"gp":{"id":"","final_price":0}}}] | E6: 2024-05-17 14:41:45 | F6: 2024-05-17 14:42:09 | G6: 21191609 | H6: Delivered | I6: Tapan Nayak | J6: 34363 | K6: Firangi Bake | L6: Shop No.4, Frist Floor, NGK Complex, Tavarekere Main Rd, 1st Stage, BTM Layout, Bengaluru, Karnataka 560029 ( Above DMart Ready) | M6: NGK Complex | N6: Bangalore | O6: 2257 | P6: 556 | Q6: 556 | R6: 556 | S6: 624 | T6: 35 | U6: 0 | V6: 12.920219,77.610520 | W6: 2.2 | X6: DEALICIOUS | Y6: UPICollect | Z6: BTM 1st Stage | AA6: FALSE | AB6: 0 | AC6: =IF(X6="","No Coupon Applied",X6) -> DEALICIOUS | AD6: =VLOOKUP(K6,'restaurant name correction'!$A$1:$B$44,2,0) -> Firangi Bake | AE6: =VLOOKUP(Z6,restaurant_area_correction!$A$1:$B$18,2,0) -> BTM | AF6: =VALUE(IFERROR(MID(D6,FIND(":",D6,FIND("total_offer_discount",D6))+1,FIND(",",D6,FIND("total_offer_discount",D6)) - FIND(":",D6,FIND("total_offer_discount",D6))-1),0)) -> 124.99 | AG6: =DATEVALUE(E6) -> 45429 | AH6: =TIMEVALUE(E6) -> 0.61232639 | AI6: =TEXT(AG6,"dddd") -> Friday | AJ6: =VLOOKUP(HOUR(Orders[[#This Row],[Time]]),$AQ$1:$AR$7,2,1) -> Afternoon | AK6: =IF(Orders[[#This Row],[rain_mode]]=0,"Sunny","Rainy") -> Sunny | AQ6: 16 | AR6: Evening
A7: 174329455765789 | B7: TRUE | C7: MDM150 | D7: [{"id":"60d51c5f-a27d-407c-9d72-c55f498dea78","super_type":"SUPERTYPE_UNSPECIFIED","total_offer_discount":149.99,"discount_share":{"swiggy_discount":15,"store_discount":134.99,"alliance_discount":0},"discount_type":"FLAT","description":"Flat ₹150 off","fixed_charges":{"gp":{"id":"","final_price":0}}}] | E7: 2024-05-10 22:20:55 | F7: 2024-05-10 22:21:01 | G7: 21191609 | H7: Delivered | I7: ARUN DYAVANAKATTI | J7: 474244 | K7: Daily Sushi | L7: No.5, 1st Floor, 9th Main Road, 5th block, Jayanagar, 560041 | M7: 5th Block | N7: Bangalore | O7: 3262 | P7: 1062 | Q7: 1062 | R7: 1062 | S7: 1050 | T7: 45 | U7: 0 | V7: 12.92243257,77.58390586 | W7: 3.2 | X7: MDM150 | Y7: Cash | Z7: Jayanagar | AA7: FALSE | AB7: 0 | AC7: =IF(X7="","No Coupon Applied",X7) -> MDM150 | AD7: =VLOOKUP(K7,'restaurant name correction'!$A$1:$B$44,2,0) -> Daily Sushi | AE7: =VLOOKUP(Z7,restaurant_area_correction!$A$1:$B$18,2,0) -> Jayanagar | AF7: =VALUE(IFERROR(MID(D7,FIND(":",D7,FIND("total_offer_discount",D7))+1,FIND(",",D7,FIND("total_offer_discount",D7)) - FIND(":",D7,FIND("total_offer_discount",D7))-1),0)) -> 149.99 | AG7: =DATEVALUE(E7) -> 45422 | AH7: =TIMEVALUE(E7) -> 0.93119213 | AI7: =TEXT(AG7,"dddd") -> Friday | AJ7: =VLOOKUP(HOUR(Orders[[#This Row],[Time]]),$AQ$1:$AR$7,2,1) -> Night | AK7: =IF(Orders[[#This Row],[rain_mode]]=0,"Sunny","Rainy") -> Sunny | AQ7: 20 | AR7: Night
A8: 174318296922309 | B8: TRUE | C8: SWIGGYIT | D8: [{"id":"7740ff94-cc8f-41cf-b6ec-d4c97cbd0060","super_type":"SUPERTYPE_UNSPECIFIED","total_offer_discount":120,"discount_share":{"swiggy_discount":67.2,"store_discount":52.8,"alliance_discount":0},"discount_type":"PERCENTAGE","description":"60% off","fixed_charges":{"gp":{"id":"","final_price":0}}}] | E8: 2024-05-10 19:14:56 | F8: 2024-05-10 19:15:01 | G8: 21191609 | H8: Delivered | I8: PARASH | J8: 434304 | K8: Paris Panini - Gourmet Sandwiches & Wraps | L8: No.690/A, 14th Main, 100ft Road, JP Nagar 2nd Phase, Bangalore 560078. | M8: JP Nagar | N8: Bangalore | O8: 2401 | P8: 440 | Q8: 440 | R8: 440 | S8: 480 | T8: 45 | U8: 0 | V8: 12.90649867,77.59165435 | W8: 2.1 | X8: SWIGGYIT | Y8: Cash | Z8: JP Nagar | AA8: FALSE | AB8: 0 | AC8: =IF(X8="","No Coupon Applied",X8) -> SWIGGYIT | AD8: =VLOOKUP(K8,'restaurant name correction'!$A$1:$B$44,2,0) -> Paris Panini | AE8: =VLOOKUP(Z8,restaurant_area_correction!$A$1:$B$18,2,0) -> JP Nagar | AF8: =VALUE(IFERROR(MID(D8,FIND(":",D8,FIND("total_offer_discount",D8))+1,FIND(",",D8,FIND("total_offer_discount",D8)) - FIND(":",D8,FIND("total_offer_discount",D8))-1),0)) -> 120 | AG8: =DATEVALUE(E8) -> 45422 | AH8: =TIMEVALUE(E8) -> 0.80203704 | AI8: =TEXT(AG8,"dddd") -> Friday | AJ8: =VLOOKUP(HOUR(Orders[[#This Row],[Time]]),$AQ$1:$AR$7,2,1) -> Evening | AK8: =IF(Orders[[#This Row],[rain_mode]]=0,"Sunny","Rainy") -> Sunny
A9: 174118005152904 | B9: TRUE | C9: SWIGGYIT | D9: [{"id":"8a02a1ac-9efe-46ea-9649-fc635c7c8618","super_type":"SUPERTYPE_UNSPECIFIED","total_offer_discount":35,"discount_share":{"swiggy_discount":0,"store_discount":35,"alliance_discount":0},"discount_type":"PERCENTAGE","description":"10% off","fixed_charges":{"gp":{"id":"","final_price":0}}}] | E9: 2024-05-08 11:36:45 | F9: 2024-05-08 11:37:28 | G9: 21191609 | H9: Delivered | I9: Sanjay Kumar Mohanty | J9: 534276 | K9: Naalnaad Mane | L9: 16,2ND FLOOR GOWRY'S BUILDING,ABOVE DOMINO'S,SY NO 13 OF AREKERE VILLAGE,BANNERGHATTA,BANGLAORE,jayanagar,B.B.M.PM south, karnataka - 560076 | M9: Mico Layout | N9: Bangalore | O9: 2824 | P9: 352 | Q9: 352 | R9: 352 | S9: 350 | T9: 36 | U9: 0 | V9: 12.89009167,77.5976944 | W9: 3.2 | X9: SWIGGYIT | Y9: UPICollect | Z9: Arekere | AA9: TRUE | AB9: 0 | AC9: =IF(X9="","No Coupon Applied",X9) -> SWIGGYIT | AD9: =VLOOKUP(K9,'restaurant name correction'!$A$1:$B$44,2,0) -> Naalnaad Mane | AE9: =VLOOKUP(Z9,restaurant_area_correction!$A$1:$B$18,2,0) -> Arekere | AF9: =VALUE(IFERROR(MID(D9,FIND(":",D9,FIND("total_offer_discount",D9))+1,FIND(",",D9,FIND("total_offer_discount",D9)) - FIND(":",D9,FIND("total_offer_discount",D9))-1),0)) -> 35 | AG9: =DATEVALUE(E9) -> 45420 | AH9: =TIMEVALUE(E9) -> 0.48385417 | AI9: =TEXT(AG9,"dddd") -> Wednesday | AJ9: =VLOOKUP(HOUR(Orders[[#This Row],[Time]]),$AQ$1:$AR$7,2,1) -> Late Morning | AK9: =IF(Orders[[#This Row],[rain_mode]]=0,"Sunny","Rainy") -> Sunny
A10: 174075356745024 | B10: FALSE | E10: 2024-05-07 23:45:56 | F10: 2024-05-07 23:46:17 | G10: 21191609 | H10: Delivered | I10: DIDAR HUSSAIN LASKAR | J10: 524936 | K10: Theobroma | L10: SHOP NO-39,SHABARI ARCADE,14TH MAIN ROAD,OPP MAX SHOWROOM, HSR LAYOUT,BANGALORE-560102, BTM Layout , B.B.M.P South, Karnataka-560102 | M10: 7th Sector | N10: Bangalore | O10: 2011 | P10: 644 | Q10: 644 | R10: 644 | S10: 275 | T10: 71 | U10: 0 | V10: 12.91135428,77.6380469 | W10: 5.2 | Y10: UPICollect | Z10: HSR Layout | AA10: TRUE | AB10: 0 | AC10: =IF(X10="","No Coupon Applied",X10) -> No Coupon Applied | AD10: =VLOOKUP(K10,'restaurant name correction'!$A$1:$B$44,2,0) -> Theobroma | AE10: =VLOOKUP(Z10,restaurant_area_correction!$A$1:$B$18,2,0) -> HSR | AF10: =VALUE(IFERROR(MID(D10,FIND(":",D10,FIND("total_offer_discount",D10))+1,FIND(",",D10,FIND("total_offer_discount",D10)) - FIND(":",D10,FIND("total_offer_discount",D10))-1),0)) -> 0 | AG10: =DATEVALUE(E10) -> 45419 | AH10: =TIMEVALUE(E10) -> 0.99023148 | AI10: =TEXT(AG10,"dddd") -> Tuesday | AJ10: =VLOOKUP(HOUR(Orders[[#This Row],[Time]]),$AQ$1:$AR$7,2,1) -> Night | AK10: =IF(Orders[[#This Row],[rain_mode]]=0,"Sunny","Rainy") -> Sunny
A11: 174067299373268 | B11: FALSE | E11: 2024-05-07 21:31:39 | F11: 2024-05-07 21:31:57 | G11: 21191609 | H11: Delivered | I11: Vijayakumar V | J11: 437065 | K11: Theobroma | L11: SHOP NO. 475, GROUND FLOOR, 39TH "C" CROSS, 9TH MAIN, 5THBLOCK, JAYANAGAR,BANGALORE, Jayanagar ,B.B.M.P South, Karnataka,560041 | M11: 5th block | N11: Bangalore | O11: 1455 | P11: 387 | Q11: 387 | R11: 387 | S11: 275 | T11: 0 | U11: 0 | V11: 12.92017647,77.5836421 | W11: 3.2 | Y11: UPICollect | Z11: Jayanagar | AA11: TRUE | AB11: 0 | AC11: =IF(X11="","No Coupon Applied",X11) -> No Coupon Applied | AD11: =VLOOKUP(K11,'restaurant name correction'!$A$1:$B$44,2,0) -> Theobroma | AE11: =VLOOKUP(Z11,restaurant_area_correction!$A$1:$B$18,2,0) -> Jayanagar | AF11: =VALUE(IFERROR(MID(D11,FIND(":",D11,FIND("total_offer_discount",D11))+1,FIND(",",D11,FIND("total_offer_discount",D11)) - FIND(":",D11,FIND("total_offer_discount",D11))-1),0)) -> 0 | AG11: =DATEVALUE(E11) -> 45419 | AH11: =TIMEVALUE(E11) -> 0.89697917 | AI11: =TEXT(AG11,"dddd") -> Tuesday | AJ11: =VLOOKUP(HOUR(Orders[[#This Row],[Time]]),$AQ$1:$AR$7,2,1) -> Night | AK11: =IF(Orders[[#This Row],[rain_mode]]=0,"Sunny","Rainy") -> Sunny
A12: 174058332503576 | B12: TRUE | C12: SWIGGYIT | D12: [{"id":"8a02a1ac-9efe-46ea-9649-fc635c7c8618","super_type":"SUPERTYPE_UNSPECIFIED","total_offer_discount":28,"discount_share":{"swiggy_discount":0,"store_discount":28,"alliance_discount":0},"discount_type":"PERCENTAGE","description":"10% off","fixed_charges":{"gp":{"id":"","final_price":0}}}] | E12: 2024-05-07 19:02:12 | F12: 2024-05-07 19:02:53 | G12: 21191609 | H12: Delivered | I12: Gangi Reddy | J12: 534276 | K12: Naalnaad Mane | L12: 16,2ND FLOOR GOWRY'S BUILDING,ABOVE DOMINO'S,SY NO 13 OF AREKERE VILLAGE,BANNERGHATTA,BANGLAORE,jayanagar,B.B.M.PM south, karnataka - 560076 | M12: Mico Layout | N12: Bangalore | O12: 4292 | P12: 320 | Q12: 320 | R12: 320 | S12: 280 | T12: 0 | U12: 0 | V12: 12.89009167,77.5976944 | W12: 3.2 | X12: SWIGGYIT | Y12: UPICollect | Z12: Arekere | AA12: FALSE | AB12: 0 | AC12: =IF(X12="","No Coupon Applied",X12) -> SWIGGYIT | AD12: =VLOOKUP(K12,'restaurant name correction'!$A$1:$B$44,2,0) -> Naalnaad Mane | AE12: =VLOOKUP(Z12,restaurant_area_correction!$A$1:$B$18,2,0) -> Arekere | AF12: =VALUE(IFERROR(MID(D12,FIND(":",D12,FIND("total_offer_discount",D12))+1,FIND(",",D12,FIND("total_offer_discount",D12)) - FIND(":",D12,FIND("total_offer_discount",D12))-1),0)) -> 28 | AG12: =DATEVALUE(E12) -> 45419 | AH12: =TIMEVALUE(E12) -> 0.79319444 | AI12: =TEXT(AG12,"dddd") -> Tuesday | AJ12: =VLOOKUP(HOUR(Orders[[#This Row],[Time]]),$AQ$1:$AR$7,2,1) -> Evening | AK12: =IF(Orders[[#This Row],[rain_mode]]=0,"Sunny","Rainy") -> Sunny
A13: 174037702433562 | B13: TRUE | C13: TRYNEW | D13: [{"id":"5c8d9a7d-f899-4dcc-998e-d3e0b2960661","super_type":"SUPERTYPE_UNSPECIFIED","total_offer_discount":80,"discount_share":{"swiggy_discount":0,"store_discount":80,"alliance_discount":0},"discount_type":"PERCENTAGE","description":"40% off","fixed_charges":{"gp":{"id":"","final_price":0}}}] | E13: 2024-05-07 13:18:22 | F13: 2024-05-07 13:18:44 | G13: 21191609 | H13: Delivered | I13: Shiba Kairi | J13: 34363 | K13: Firangi Bake | L13: Shop No.4, Frist Floor, NGK Complex, Tavarekere Main Rd, 1st Stage, BTM Layout, Bengaluru, Karnataka 560029 ( Above DMart Ready) | M13: NGK Complex | N13: Bangalore | O13: 2730 | P13: 320 | Q13: 320 | R13: 320 | S13: 325 | T13: 0 | U13: 0 | V13: 12.920219,77.610520 | W13: 2.2 | X13: TRYNEW | Y13: UPICollect | Z13: BTM 1st Stage | AA13: FALSE | AB13: 0 | AC13: =IF(X13="","No Coupon Applied",X13) -> TRYNEW | AD13: =VLOOKUP(K13,'restaurant name correction'!$A$1:$B$44,2,0) -> Firangi Bake | AE13: =VLOOKUP(Z13,restaurant_area_correction!$A$1:$B$18,2,0) -> BTM | AF13: =VALUE(IFERROR(MID(D13,FIND(":",D13,FIND("total_offer_discount",D13))+1,FIND(",",D13,FIND("total_offer_discount",D13)) - FIND(":",D13,FIND("total_offer_discount",D13))-1),0)) -> 80 | AG13: =DATEVALUE(E13) -> 45419 | AH13: =TIMEVALUE(E13) -> 0.5544213 | AI13: =TEXT(AG13,"dddd") -> Tuesday | AJ13: =VLOOKUP(HOUR(Orders[[#This Row],[Time]]),$AQ$1:$AR$7,2,1) -> Afternoon | AK13: =IF(Orders[[#This Row],[rain_mode]]=0,"Sunny","Rainy") -> Sunny
A14: 174026206595017 | B14: TRUE | C14: SWIGGYIT | D14: [{"id":"28bf3ebb-4a69-4a92-88a4-f491a5f86e17","super_type":"SUPERTYPE_UNSPECIFIED","total_offer_discount":23.9,"discount_share":{"swiggy_discount":0,"store_discount":23.9,"alliance_discount":0},"discount_type":"PERCENTAGE","description":"10% off","fixed_charges":{"gp":{"id":"","final_price":0}}}] | E14: 2024-05-07 10:06:46 | F14: 2024-05-07 10:07:00 | G14: 21191609 | H14: Delivered | I14: Harikrishna R | J14: 630473 | K14: Rasayan | L14: 652,13th cross,29th main road BTM 2nd stage,560078, Bangalore Karnataka | M14: Health Bar | N14: Bangalore | O14: 1927 | P14: 275 | Q14: 275 | R14: 275 | S14: 239 | T14: 10 | U14: 0 | V14: 12.907799,77.613487 | W14: 2.5 | X14: SWIGGYIT | Y14: UPICollect | Z14: BTM 2nd Stage | AA14: TRUE | AB14: 0 | AC14: =IF(X14="","No Coupon Applied",X14) -> SWIGGYIT | AD14: =VLOOKUP(K14,'restaurant name correction'!$A$1:$B$44,2,0) -> Rasayan | AE14: =VLOOKUP(Z14,restaurant_area_correction!$A$1:$B$18,2,0) -> BTM | AF14: =VALUE(IFERROR(MID(D14,FIND(":",D14,FIND("total_offer_discount",D14))+1,FIND(",",D14,FIND("total_offer_discount",D14)) - FIND(":",D14,FIND("total_offer_discount",D14))-1),0)) -> 23.9 | AG14: =DATEVALUE(E14) -> 45419 | AH14: =TIMEVALUE(E14) -> 0.42136574 | AI14: =TEXT(AG14,"dddd") -> Tuesday | AJ14: =VLOOKUP(HOUR(Orders[[#This Row],[Time]]),$AQ$1:$AR$7,2,1) -> Late Morning | AK14: =IF(Orders[[#This Row],[rain_mode]]=0,"Sunny","Rainy") -> Sunny
A15: 173972919485563 | B15: TRUE | C15: SWIGGYIT | D15: [{"id":"137a1aed-678a-41ce-ac11-088fcce35f29","super_type":"SUPERTYPE_UNSPECIFIED","total_offer_discount":100,"discount_share":{"swiggy_discount":48,"store_discount":52,"alliance_discount":0},"discount_type":"PERCENTAGE","description":"50% off","fixed_charges":{"gp":{"id":"","final_price":0}}}] | E15: 2024-05-06 19:18:39 | F15: 2024-05-06 19:19:03 | G15: 21191609 | H15: Delivered | I15: Puran Singh | J15: 434304 | K15: Paris Panini - Gourmet Sandwiches & Wraps | L15: No.690/A, 14th Main, 100ft Road, JP Nagar 2nd Phase, Bangalore 560078. | M15: JP Nagar | N15: Bangalore | O15: 2041 | P15: 334 | Q15: 334 | R15: 334 | S15: 385 | T15: 42 | U15: 0 | V15: 12.90649867,77.59165435 | W15: 2.1 | X15: SWIGGYIT | Y15: UPICollect | Z15: JP Nagar | AA15: FALSE | AB15: 0 | AC15: =IF(X15="","No Coupon Applied",X15) -> SWIGGYIT | AD15: =VLOOKUP(K15,'restaurant name correction'!$A$1:$B$44,2,0) -> Paris Panini | AE15: =VLOOKUP(Z15,restaurant_area_correction!$A$1:$B$18,2,0) -> JP Nagar | AF15: =VALUE(IFERROR(MID(D15,FIND(":",D15,FIND("total_offer_discount",D15))+1,FIND(",",D15,FIND("total_offer_discount",D15)) - FIND(":",D15,FIND("total_offer_discount",D15))-1),0)) -> 100 | AG15: =DATEVALUE(E15) -> 45418 | AH15: =TIMEVALUE(E15) -> 0.80461806 | AI15: =TEXT(AG15,"dddd") -> Monday | AJ15: =VLOOKUP(HOUR(Orders[[#This Row],[Time]]),$AQ$1:$AR$7,2,1) -> Evening | AK15: =IF(Orders[[#This Row],[rain_mode]]=0,"Sunny","Rainy") -> Sunny
A16: 173961191807457 | B16: FALSE | E16: 2024-05-06 16:03:12 | F16: 2024-05-06 16:03:45 | G16: 21191609 | H16: Delivered | I16: Ash Narayan Das | J16: 694704 | K16: Love And Crumble | L16: NO 307, LALEHZAR APARTMENTS PALACE ROAD SHIVAJINAGARA B.B.M.P EAST KARNATAKA | M16: Lalehzar Apartments Palace Road | N16: Bangalore | O16: 4528 | P16: 509 | Q16: 509 | R16: 509 | S16: 370 | T16: 0 | U16: 0 | V16: 12.98505012,77.5880017 | W16: 10.2 | Y16: UPICollect | Z16: Malleshwaram | AA16: TRUE | AB16: 0 | AC16: =IF(X16="","No Coupon Applied",X16) -> No Coupon Applied | AD16: =VLOOKUP(K16,'restaurant name correction'!$A$1:$B$44,2,0) -> Love And Crumble | AE16: =VLOOKUP(Z16,restaurant_area_correction!$A$1:$B$18,2,0) -> Malleshwaram | AF16: =VALUE(IFERROR(MID(D16,FIND(":",D16,FIND("total_offer_discount",D16))+1,FIND(",",D16,FIND("total_offer_discount",D16)) - FIND(":",D16,FIND("total_offer_discount",D16))-1),0)) -> 0 | AG16: =DATEVALUE(E16) -> 45418 | AH16: =TIMEVALUE(E16) -> 0.66888889 | AI16: =TEXT(AG16,"dddd") -> Monday | AJ16: =VLOOKUP(HOUR(Orders[[#This Row],[Time]]),$AQ$1:$AR$7,2,1) -> Evening | AK16: =IF(Orders[[#This Row],[rain_mode]]=0,"Sunny","Rainy") -> Sunny
A17: 173953404362535 | B17: TRUE | C17: DEALICIOUS | D17: [{"id":"8ecc3140-454d-483f-810e-78be04d68af5","super_type":"SUPERTYPE_UNSPECIFIED","total_offer_discount":124.99,"discount_share":{"swiggy_discount":0,"store_discount":124.99,"alliance_discount":0},"discount_type":"FLAT","description":"FLAT125 off","fixed_charges":{"gp":{"id":"","final_price":0}}}] | E17: 2024-05-06 13:53:24 | F17: 2024-05-06 13:53:46 | G17: 21191609 | H17: Delivered | I17: MRITYUNJAY HALDER | J17: 34381 | K17: Firangi Bake | L17: No 87/15/638/2 Nanjappa garden, Katha no - 1785/87/15/638/2, Arekere Village, begur hobali, Bangalore South taluk, Bangalore - 560076 | M17: Begur Hobali | N17: Bangalore | O17: 3728 | P17: 556 | Q17: 556 | R17: 556 | S17: 624 | T17: 48 | U17: 0 | V17: 12.885643,77.602120 | W17: 3.4 | X17: DEALICIOUS | Y17: UPICollect | Z17: Arekere | AA17: FALSE | AB17: 0 | AC17: =IF(X17="","No Coupon Applied",X17) -> DEALICIOUS | AD17: =VLOOKUP(K17,'restaurant name correction'!$A$1:$B$44,2,0) -> Firangi Bake | AE17: =VLOOKUP(Z17,restaurant_area_correction!$A$1:$B$18,2,0) -> Arekere | AF17: =VALUE(IFERROR(MID(D17,FIND(":",D17,FIND("total_offer_discount",D17))+1,FIND(",",D17,FIND("total_offer_discount",D17)) - FIND(":",D17,FIND("total_offer_discount",D17))-1),0)) -> 124.99 | AG17: =DATEVALUE(E17) -> 45418 | AH17: =TIMEVALUE(E17) -> 0.57875 | AI17: =TEXT(AG17,"dddd") -> Monday | AJ17: =VLOOKUP(HOUR(Orders[[#This Row],[Time]]),$AQ$1:$AR$7,2,1) -> Afternoon | AK17: =IF(Orders[[#This Row],[rain_mode]]=0,"Sunny","Rainy") -> Sunny
A18: 173934793528823 | B18: TRUE | C18: SWIGGYIT | D18: [{"id":"28bf3ebb-4a69-4a92-88a4-f491a5f86e17","super_type":"SUPERTYPE_UNSPECIFIED","total_offer_discount":23.9,"discount_share":{"swiggy_discount":0,"store_discount":23.9,"alliance_discount":0},"discount_type":"PERCENTAGE","description":"10% off","fixed_charges":{"gp":{"id":"","final_price":0}}}] | E18: 2024-05-06 08:43:13 | F18: 2024-05-06 08:43:38 | G18: 21191609 | H18: Delivered | I18: THARUN N | J18: 630473 | K18: Rasayan | L18: 652,13th cross,29th main road BTM 2nd stage,560078, Bangalore Karnataka | M18: Health Bar | N18: Bangalore | O18: 2470 | P18: 242 | Q18: 242 | R18: 242 | S18: 239 | T18: 43 | U18: 0 | V18: 12.907799,77.613487 | W18: 2.5 | X18: SWIGGYIT | Y18: UPICollect | Z18: BTM 2nd Stage | AA18: FALSE | AB18: 0 | AC18: =IF(X18="","No Coupon Applied",X18) -> SWIGGYIT | AD18: =VLOOKUP(K18,'restaurant name correction'!$A$1:$B$44,2,0) -> Rasayan | AE18: =VLOOKUP(Z18,restaurant_area_correction!$A$1:$B$18,2,0) -> BTM | AF18: =VALUE(IFERROR(MID(D18,FIND(":",D18,FIND("total_offer_discount",D18))+1,FIND(",",D18,FIND("total_offer_discount",D18)) - FIND(":",D18,FIND("total_offer_discount",D18))-1),0)) -> 23.9 | AG18: =DATEVALUE(E18) -> 45418 | AH18: =TIMEVALUE(E18) -> 0.36334491 | AI18: =TEXT(AG18,"dddd") -> Monday | AJ18: =VLOOKUP(HOUR(Orders[[#This Row],[Time]]),$AQ$1:$AR$7,2,1) -> Late Morning | AK18: =IF(Orders[[#This Row],[rain_mode]]=0,"Sunny","Rainy") -> Sunny
A19: 173886476249693 | B19: TRUE | C19: SWIGGYIT | D19: [{"id":"28bf3ebb-4a69-4a92-88a4-f491a5f86e17","super_type":"SUPERTYPE_UNSPECIFIED","total_offer_discount":40,"discount_share":{"swiggy_discount":0,"store_discount":40,"alliance_discount":0},"discount_type":"PERCENTAGE","description":"10% off","fixed_charges":{"gp":{"id":"","final_price":0}}}] | E19: 2024-05-05 19:17:56 | F19: 2024-05-05 19:18:22 | G19: 21191609 | H19: Delivered | I19: SrinivasSrini | J19: 630473 | K19: Rasayan | L19: 652,13th cross,29th main road BTM 2nd stage,560078, Bangalore Karnataka | M19: Health Bar | N19: Bangalore | O19: 1594 | P19: 487 | Q19: 487 | R19: 487 | S19: 478 | T19: 36 | U19: 0 | V19: 12.907799,77.613487 | W19: 2.5 | X19: SWIGGYIT | Y19: UPICollect | Z19: BTM 2nd Stage | AA19: TRUE | AB19: 0 | AC19: =IF(X19="","No Coupon Applied",X19) -> SWIGGYIT | AD19: =VLOOKUP(K19,'restaurant name correction'!$A$1:$B$44,2,0) -> Rasayan | AE19: =VLOOKUP(Z19,restaurant_area_correction!$A$1:$B$18,2,0) -> BTM | AF19: =VALUE(IFERROR(MID(D19,FIND(":",D19,FIND("total_offer_discount",D19))+1,FIND(",",D19,FIND("total_offer_discount",D19)) - FIND(":",D19,FIND("total_offer_discount",D19))-1),0)) -> 40 | AG19: =DATEVALUE(E19) -> 45417 | AH19: =TIMEVALUE(E19) -> 0.80412037 | AI19: =TEXT(AG19,"dddd") -> Sunday | AJ19: =VLOOKUP(HOUR(Orders[[#This Row],[Time]]),$AQ$1:$AR$7,2,1) -> Evening | AK19: =IF(Orders[[#This Row],[rain_mode]]=0,"Sunny","Rainy") -> Sunny
A20: 173848012476255 | B20: TRUE | C20: JUMBO | D20: [{"id":"7b5f26f9-18b8-4c51-aed1-b1e142eba2ae","super_type":"SUPERTYPE_UNSPECIFIED","total_offer_discount":149.4,"discount_share":{"swiggy_discount":0,"store_discount":149.4,"alliance_discount":0},"discount_type":"PERCENTAGE","description":"30% off","fixed_charges":{"gp":{"id":"","final_price":0}}}] | E20: 2024-05-05 08:36:52 | F20: 2024-05-05 08:37:10 | G20: 21191609 | H20: Delivered | I20: Rajesh Kumar | J20: 630473 | K20: Rasayan | L20: 652,13th cross,29th main road BTM 2nd stage,560078, Bangalore Karnataka | M20: Health Bar | N20: Bangalore | O20: 2999 | P20: 392 | Q20: 392 | R20: 392 | S20: 498 | T20: 43 | U20: 0 | V20: 12.907799,77.613487 | W20: 2.5 | X20: JUMBO | Y20: UPICollect | Z20: BTM 2nd Stage | AA20: FALSE | AB20: 0 | AC20: =IF(X20="","No Coupon Applied",X20) -> JUMBO | AD20: =VLOOKUP(K20,'restaurant name correction'!$A$1:$B$44,2,0) -> Rasayan | AE20: =VLOOKUP(Z20,restaurant_area_correction!$A$1:$B$18,2,0) -> BTM | AF20: =VALUE(IFERROR(MID(D20,FIND(":",D20,FIND("total_offer_discount",D20))+1,FIND(",",D20,FIND("total_offer_discount",D20)) - FIND(":",D20,FIND("total_offer_discount",D20))-1),0)) -> 149.4 | AG20: =DATEVALUE(E20) -> 45417 | AH20: =TIMEVALUE(E20) -> 0.35893519 | AI20: =TEXT(AG20,"dddd") -> Sunday | AJ20: =VLOOKUP(HOUR(Orders[[#This Row],[Time]]),$AQ$1:$AR$7,2,1) -> Late Morning | AK20: =IF(Orders[[#This Row],[rain_mode]]=0,"Sunny","Rainy") -> Sunny
A21: 173787961265182 | B21: TRUE | C21: TRYNEW | D21: [{"id":"903b3cd1-104b-4bdd-94d3-96daaea1a80b","super_type":"SUPERTYPE_UNSPECIFIED","total_offer_discount":44.99,"discount_share":{"swiggy_discount":0,"store_discount":44.99,"alliance_discount":0},"discount_type":"PERCENTAGE","description":"15% off","fixed_charges":{"gp":{"id":"","final_price":0}}}] | E21: 2024-05-04 15:56:01 | F21: 2024-05-04 15:56:19 | G21: 21191609 | H21: Delivered | I21: Surendra J | J21: 534276 | K21: Naalnaad Mane | L21: 16,2ND FLOOR GOWRY'S BUILDING,ABOVE DOMINO'S,SY NO 13 OF AREKERE VILLAGE,BANNERGHATTA,BANGLAORE,jayanagar,B.B.M.PM south, karnataka - 560076 | M21: Mico Layout | N21: Bangalore | O21: 2684 | P21: 680 | Q21: 680 | R21: 680 | S21: 660 | T21: 33 | U21: 0 | V21: 12.89009167,77.5976944 | W21: 2.7 | X21: TRYNEW | Y21: UPICollect | Z21: Arekere | AA21: TRUE | AB21: 0 | AC21: =IF(X21="","No Coupon Applied",X21) -> TRYNEW | AD21: =VLOOKUP(K21,'restaurant name correction'!$A$1:$B$44,2,0) -> Naalnaad Mane | AE21: =VLOOKUP(Z21,restaurant_area_correction!$A$1:$B$18,2,0) -> Arekere | AF21: =VALUE(IFERROR(MID(D21,FIND(":",D21,FIND("total_offer_discount",D21))+1,FIND(",",D21,FIND("total_offer_discount",D21)) - FIND(":",D21,FIND("total_offer_discount",D21))-1),0)) -> 44.99 | AG21: =DATEVALUE(E21) -> 45416 | AH21: =TIMEVALUE(E21) -> 0.66390046 | AI21: =TEXT(AG21,"dddd") -> Saturday | AJ21: =VLOOKUP(HOUR(Orders[[#This Row],[Time]]),$AQ$1:$AR$7,2,1) -> Afternoon | AK21: =IF(Orders[[#This Row],[rain_mode]]=0,"Sunny","Rainy") -> Sunny
A22: 173627120783219 | B22: TRUE | C22: MISSEDYOU | D22: [{"id":"bcdcaa8c-6d73-46c7-af56-3b6dc93e207a","super_type":"SUPERTYPE_UNSPECIFIED","total_offer_discount":60,"discount_share":{"swiggy_discount":12,"store_discount":48,"alliance_discount":0},"discount_type":"PERCENTAGE","description":"30% off","fixed_charges":{"gp":{"id":"","final_price":0}}}] | E22: 2024-05-02 19:15:20 | F22: 2024-05-02 19:15:26 | G22: 21191609 | H22: Delivered | I22: KAMAL CHETRY | J22: 35953 | K22: Homely | L22: No. 135/14, 100ft Ring Road, 15th Cross, J.P.Nagar, 3rd Phase, Bengaluru.560076 | M22: 3rd Phase | N22: Bangalore | O22: 1654 | P22: 214 | Q22: 214 | R22: 214 | S22: 239 | T22: 54 | U22: 0 | V22: 12.906291,77.596256 | W22: 1.6 | X22: MISSEDYOU | Y22: Cash | Z22: JP Nagar | AA22: TRUE | AB22: 2 | AC22: =IF(X22="","No Coupon Applied",X22) -> MISSEDYOU | AD22: =VLOOKUP(K22,'restaurant name correction'!$A$1:$B$44,2,0) -> Homely | AE22: =VLOOKUP(Z22,restaurant_area_correction!$A$1:$B$18,2,0) -> JP Nagar | AF22: =VALUE(IFERROR(MID(D22,FIND(":",D22,FIND("total_offer_discount",D22))+1,FIND(",",D22,FIND("total_offer_discount",D22)) - FIND(":",D22,FIND("total_offer_discount",D22))-1),0)) -> 60 | AG22: =DATEVALUE(E22) -> 45414 | AH22: =TIMEVALUE(E22) -> 0.80231481 | AI22: =TEXT(AG22,"dddd") -> Thursday | AJ22: =VLOOKUP(HOUR(Orders[[#This Row],[Time]]),$AQ$1:$AR$7,2,1) -> Evening | AK22: =IF(Orders[[#This Row],[rain_mode]]=0,"Sunny","Rainy") -> Rainy
A23: 173528899495632 | B23: TRUE | C23: TRYNEW | D23: [{"id":"6efa58fe-50e0-4c94-aadd-f2cf8ce25c67","super_type":"SUPERTYPE_UNSPECIFIED","total_offer_discount":99.99000000000001,"discount_share":{"swiggy_discount":47.99,"store_discount":52,"alliance_discount":0},"discount_type":"PERCENTAGE","description":"50% off","fixed_charges":{"gp":{"id":"","final_price":0}}}] | E23: 2024-05-01 15:58:19 | F23: 2024-05-01 15:58:57 | G23: 21191609 | H23: Delivered | I23: Sakti Prasad Sundaray | J23: 434304 | K23: Paris Panini - Gourmet Sandwiches & Wraps | L23: No.690/A, 14th Main, 100ft Road, JP Nagar 2nd Phase, Bangalore 560078. | M23: JP Nagar | N23: Bangalore | O23: 2161 | P23: 696 | Q23: 696 | R23: 696 | S23: 680 | T23: 36 | U23: 0 | V23: 12.90649867,77.59165435 | W23: 2.1 | X23: TRYNEW | Y23: UPICollect | Z23: JP Nagar | AA23: FALSE | AB23: 0 | AC23: =IF(X23="","No Coupon Applied",X23) -> TRYNEW | AD23: =VLOOKUP(K23,'restaurant name correction'!$A$1:$B$44,2,0) -> Paris Panini | AE23: =VLOOKUP(Z23,restaurant_area_correction!$A$1:$B$18,2,0) -> JP Nagar | AF23: =VALUE(IFERROR(MID(D23,FIND(":",D23,FIND("total_offer_discount",D23))+1,FIND(",",D23,FIND("total_offer_discount",D23)) - FIND(":",D23,FIND("total_offer_discount",D23))-1),0)) -> 99.99 | AG23: =DATEVALUE(E23) -> 45413 | AH23: =TIMEVALUE(E23) -> 0.66549769 | AI23: =TEXT(AG23,"dddd") -> Wednesday | AJ23: =VLOOKUP(HOUR(Orders[[#This Row],[Time]]),$AQ$1:$AR$7,2,1) -> Afternoon | AK23: =IF(Orders[[#This Row],[rain_mode]]=0,"Sunny","Rainy") -> Sunny
A24: 173508364352211 | B24: TRUE | C24: JUMBO | D24: [{"id":"7b5f26f9-18b8-4c51-aed1-b1e142eba2ae","super_type":"SUPERTYPE_UNSPECIFIED","total_offer_discount":148.8,"discount_share":{"swiggy_discount":0,"store_discount":148.8,"alliance_discount":0},"discount_type":"PERCENTAGE","description":"30% off","fixed_charges":{"gp":{"id":"","final_price":0}}}] | E24: 2024-05-01 10:16:04 | F24: 2024-05-01 10:16:24 | G24: 21191609 | H24: Delivered | I24: Shaik Yaseen | J24: 630473 | K24: Rasayan | L24: 652,13th cross,29th main road BTM 2nd stage,560078, Bangalore Karnataka | M24: Health Bar | N24: Bangalore | O24: 2775 | P24: 399 | Q24: 399 | R24: 399 | S24: 496 | T24: 43 | U24: 0 | V24: 12.907799,77.613487 | W24: 2.5 | X24: JUMBO | Y24: UPICollect | Z24: BTM 2nd Stage | AA24: FALSE | AB24: 0 | AC24: =IF(X24="","No Coupon Applied",X24) -> JUMBO | AD24: =VLOOKUP(K24,'restaurant name correction'!$A$1:$B$44,2,0) -> Rasayan | AE24: =VLOOKUP(Z24,restaurant_area_correction!$A$1:$B$18,2,0) -> BTM | AF24: =VALUE(IFERROR(MID(D24,FIND(":",D24,FIND("total_offer_discount",D24))+1,FIND(",",D24,FIND("total_offer_discount",D24)) - FIND(":",D24,FIND("total_offer_discount",D24))-1),0)) -> 148.8 | AG24: =DATEVALUE(E24) -> 45413 | AH24: =TIMEVALUE(E24) -> 0.42782407 | AI24: =TEXT(AG24,"dddd") -> Wednesday | AJ24: =VLOOKUP(HOUR(Orders[[#This Row],[Time]]),$AQ$1:$AR$7,2,1) -> Late Morning | AK24: =IF(Orders[[#This Row],[rain_mode]]=0,"Sunny","Rainy") -> Sunny
A25: 173162395766364 | B25: TRUE | C25: JUMBO | D25: [{"id":"7b5f26f9-18b8-4c51-aed1-b1e142eba2ae","super_type":"SUPERTYPE_UNSPECIFIED","total_offer_discount":149.99,"discount_share":{"swiggy_discount":0,"store_discount":149.99,"alliance_discount":0},"discount_type":"PERCENTAGE","description":"30% off","fixed_charges":{"gp":{"id":"","final_price":0}}}] | E25: 2024-04-27 10:09:55 | F25: 2024-04-27 10:10:09 | G25: 21191609 | H25: Delivered | I25: RIYAZ AHMED | J25: 630473 | K25: Rasayan | L25: 652,13th cross,29th main road BTM 2nd stage,560078, Bangalore Karnataka | M25: Health Bar | N25: Bangalore | O25: 2197 | P25: 489 | Q25: 489 | R25: 489 | S25: 580 | T25: 43 | U25: 0 | V25: 12.907799,77.613487 | W25: 2.5 | X25: JUMBO | Y25: UPICollect | Z25: BTM 2nd Stage | AA25: FALSE | AB25: 0 | AC25: =IF(X25="","No Coupon Applied",X25) -> JUMBO | AD25: =VLOOKUP(K25,'restaurant name correction'!$A$1:$B$44,2,0) -> Rasayan | AE25: =VLOOKUP(Z25,restaurant_area_correction!$A$1:$B$18,2,0) -> BTM | AF25: =VALUE(IFERROR(MID(D25,FIND(":",D25,FIND("total_offer_discount",D25))+1,FIND(",",D25,FIND("total_offer_discount",D25)) - FIND(":",D25,FIND("total_offer_discount",D25))-1),0)) -> 149.99 | AG25: =DATEVALUE(E25) -> 45409 | AH25: =TIMEVALUE(E25) -> 0.42355324 | AI25: =TEXT(AG25,"dddd") -> Saturday | AJ25: =VLOOKUP(HOUR(Orders[[#This Row],[Time]]),$AQ$1:$AR$7,2,1) -> Late Morning | AK25: =IF(Orders[[#This Row],[rain_mode]]=0,"Sunny","Rainy") -> Sunny
A26: 173162271836174 | B26: FALSE | E26: 2024-04-27 10:07:51 | F26: 2024-04-27 10:08:09 | G26: 21191609 | H26: cancelled | I26: 0 | J26: 630473 | K26: Rasayan | L26: 652,13th cross,29th main road BTM 2nd stage,560078, Bangalore Karnataka | M26: Health Bar | N26: Bangalore | O26: 0 | P26: 646 | Q26: 646 | R26: 646 | S26: 580 | T26: 43 | U26: 0 | V26: 12.907799,77.613487 | W26: 1.9 | Y26: UPICollect | Z26: BTM 2nd Stage | AA26: FALSE | AB26: 0 | AC26: =IF(X26="","No Coupon Applied",X26) -> No Coupon Applied | AD26: =VLOOKUP(K26,'restaurant name correction'!$A$1:$B$44,2,0) -> Rasayan | AE26: =VLOOKUP(Z26,restaurant_area_correction!$A$1:$B$18,2,0) -> BTM | AF26: =VALUE(IFERROR(MID(D26,FIND(":",D26,FIND("total_offer_discount",D26))+1,FIND(",",D26,FIND("total_offer_discount",D26)) - FIND(":",D26,FIND("total_offer_discount",D26))-1),0)) -> 0 | AG26: =DATEVALUE(E26) -> 45409 | AH26: =TIMEVALUE(E26) -> 0.42211806 | AI26: =TEXT(AG26,"dddd") -> Saturday | AJ26: =VLOOKUP(HOUR(Orders[[#This Row],[Time]]),$AQ$1:$AR$7,2,1) -> Late Morning | AK26: =IF(Orders[[#This Row],[rain_mode]]=0,"Sunny","Rainy") -> Sunny
A27: 173021459533483 | B27: TRUE | C27: TRYNEW | D27: [{"id":"f90d8119-321f-4158-a454-d7576a8e0a65","super_type":"SUPERTYPE_UNSPECIFIED","total_offer_discount":75,"discount_share":{"swiggy_discount":18.75,"store_discount":56.25,"alliance_discount":0},"discount_type":"PERCENTAGE","description":"30% off","fixed_charges":{"gp":{"id":"","final_price":0}}}] | E27: 2024-04-25 19:00:59 | F27: 2024-04-25 19:01:33 | G27: 21191609 | H27: Delivered | I27: RAJESH CHETRY | J27: 260968 | K27: Chowman | L27: SAI DURGA ENCLAVE, KATHA NO 1099, AND NO 833/1, GROUND FLOOR, BELLENDUR VILLAGE, VARTHUR HOBLI, BANGALORE, Mahadevapura , B.B.M.P East, Karnataka-560037 | M27: Sai Durga Enclave | N27: Bangalore | O27: 1950 | P27: 208 | Q27: 208 | R27: 208 | S27: 260 | T27: 40 | U27: 0 | V27: 12.92314229,77.6713331 | W27: 3.3 | X27: TRYNEW | Y27: UPICollect | Z27: Bellandur | AA27: TRUE | AB27: 0 | AC27: =IF(X27="","No Coupon Applied",X27) -> TRYNEW | AD27: =VLOOKUP(K27,'restaurant name correction'!$A$1:$B$44,2,0) -> Chowman | AE27: =VLOOKUP(Z27,restaurant_area_correction!$A$1:$B$18,2,0) -> Bellandur | AF27: =VALUE(IFERROR(MID(D27,FIND(":",D27,FIND("total_offer_discount",D27))+1,FIND(",",D27,FIND("total_offer_discount",D27)) - FIND(":",D27,FIND("total_offer_discount",D27))-1),0)) -> 75 | AG27: =DATEVALUE(E27) -> 45407 | AH27: =TIMEVALUE(E27) -> 0.79234954 | AI27: =TEXT(AG27,"dddd") -> Thursday | AJ27: =VLOOKUP(HOUR(Orders[[#This Row],[Time]]),$AQ$1:$AR$7,2,1) -> Evening | AK27: =IF(Orders[[#This Row],[rain_mode]]=0,"Sunny","Rainy") -> Sunny
A28: 172937451496694 | B28: TRUE | C28: MISSEDYOU | D28: [{"id":"12337c67-3996-4380-afdd-b7cf7e3de7a3","super_type":"SUPERTYPE_UNSPECIFIED","total_offer_discount":100,"discount_share":{"swiggy_discount":48,"store_discount":52,"alliance_discount":0},"discount_type":"PERCENTAGE","description":"50% off","fixed_charges":{"gp":{"id":"","final_price":0}}}] | E28: 2024-04-24 19:40:51 | F28: 2024-04-24 19:41:11 | G28: 21191609 | H28: Delivered | I28: K Babu | J28: 742267 | K28: Paris Panini - Gourmet Sandwiches & Wraps | L28: Counter No. 23, 24 & 33, No. 53/2, Doddakannelli Village, Varthur Hobli, Bangalore, Mahadevapura , B.B.M.P East, Karnataka-560038 | M28: Sarjapur Road | N28: Bangalore | O28: 2384 | P28: 344 | Q28: 344 | R28: 344 | S28: 395 | T28: 61 | U28: 0 | V28: 12.90906249,77.68766132 | W28: 5.4 | X28: MISSEDYOU | Y28: UPICollect | Z28: Bellandur Sarjapur | AA28: TRUE | AB28: 0 | AC28: =IF(X28="","No Coupon Applied",X28) -> MISSEDYOU | AD28: =VLOOKUP(K28,'restaurant name correction'!$A$1:$B$44,2,0) -> Paris Panini | AE28: =VLOOKUP(Z28,restaurant_area_correction!$A$1:$B$18,2,0) -> Bellandur | AF28: =VALUE(IFERROR(MID(D28,FIND(":",D28,FIND("total_offer_discount",D28))+1,FIND(",",D28,FIND("total_offer_discount",D28)) - FIND(":",D28,FIND("total_offer_discount",D28))-1),0)) -> 100 | AG28: =DATEVALUE(E28) -> 45406 | AH28: =TIMEVALUE(E28) -> 0.82003472 | AI28: =TEXT(AG28,"dddd") -> Wednesday | AJ28: =VLOOKUP(HOUR(Orders[[#This Row],[Time]]),$AQ$1:$AR$7,2,1) -> Evening | AK28: =IF(Orders[[#This Row],[rain_mode]]=0,"Sunny","Rainy") -> Sunny
A29: 172865582370674 | B29: TRUE | C29: SWIGGYIT | D29: [{"id":"a95119de-61b8-489b-ad8b-1cf7a5d62a5e","super_type":"SUPERTYPE_UNSPECIFIED","total_offer_discount":50,"discount_share":{"swiggy_discount":15,"store_discount":35,"alliance_discount":0},"discount_type":"PERCENTAGE","description":"20% off","fixed_charges":{"gp":{"id":"","final_price":0}}}] | E29: 2024-04-23 23:43:02 | F29: 2024-04-23 23:43:23 | G29: 21191609 | H29: Delivered | I29: Kapsi Mohammed Tufail | J29: 29349 | K29: Frozen Bottle - Milkshakes, Desserts And Ice Cream | L29: 88, Celler Floor, 17th Cross, 14th main, Sector - 4, HSR, Bangalore | M29: HSR Layout | N29: Bangalore | O29: 1985 | P29: 301 | Q29: 301 | R29: 301 | S29: 289 | T29: 50 | U29: 0 | V29: 12.91233118,77.63839138 | W29: 1.7 | X29: SWIGGYIT | Y29: UPICollect | Z29: HSR Layout | AA29: TRUE | AB29: 0 | AC29: =IF(X29="","No Coupon Applied",X29) -> SWIGGYIT | AD29: =VLOOKUP(K29,'restaurant name correction'!$A$1:$B$44,2,0) -> Frozen Bottle | AE29: =VLOOKUP(Z29,restaurant_area_correction!$A$1:$B$18,2,0) -> HSR | AF29: =VALUE(IFERROR(MID(D29,FIND(":",D29,FIND("total_offer_discount",D29))+1,FIND(",",D29,FIND("total_offer_discount",D29)) - FIND(":",D29,FIND("total_offer_discount",D29))-1),0)) -> 50 | AG29: =DATEVALUE(E29) -> 45405 | AH29: =TIMEVALUE(E29) -> 0.98821759 | AI29: =TEXT(AG29,"dddd") -> Tuesday | AJ29: =VLOOKUP(HOUR(Orders[[#This Row],[Time]]),$AQ$1:$AR$7,2,1) -> Night | AK29: =IF(Orders[[#This Row],[rain_mode]]=0,"Sunny","Rainy") -> Sunny
A30: 172849812190412 | B30: TRUE | C30: TRYNEW | D30: [{"id":"768dad50-eef1-40d7-bfd4-5327ee71bb5a","super_type":"SUPERTYPE_UNSPECIFIED","total_offer_discount":60,"discount_share":{"swiggy_discount":0,"store_discount":60,"alliance_discount":0},"discount_type":"PERCENTAGE","description":"30% off","fixed_charges":{"gp":{"id":"","final_price":0}}}] | E30: 2024-04-23 19:20:12 | F30: 2024-04-23 19:20:29 | G30: 21191609 | H30: Delivered | I30: ANSHUMAN DAS | J30: 34366 | K30: Firangi Bake | L30: SHOP NO 2318,HSR LAYOUT SECTOR ONE,NEAR NIFT COLLEGE,BANGALORE | M30: Near NIFT College, Sector 1 | N30: Bangalore | O30: 1375 | P30: 310 | Q30: 310 | R30: 310 | S30: 325 | T30: 35 | U30: 0 | V30: 12.912101,77.65163400000006 | W30: 0.8 | X30: TRYNEW | Y30: UPICollect | Z30: HSR Layout | AA30: FALSE | AB30: 0 | AC30: =IF(X30="","No Coupon Applied",X30) -> TRYNEW | AD30: =VLOOKUP(K30,'restaurant name correction'!$A$1:$B$44,2,0) -> Firangi Bake | AE30: =VLOOKUP(Z30,restaurant_area_correction!$A$1:$B$18,2,0) -> HSR | AF30: =VALUE(IFERROR(MID(D30,FIND(":",D30,FIND("total_offer_discount",D30))+1,FIND(",",D30,FIND("total_offer_discount",D30)) - FIND(":",D30,FIND("total_offer_discount",D30))-1),0)) -> 60 | AG30: =DATEVALUE(E30) -> 45405 | AH30: =TIMEVALUE(E30) -> 0.80569444 | AI30: =TEXT(AG30,"dddd") -> Tuesday | AJ30: =VLOOKUP(HOUR(Orders[[#This Row],[Time]]),$AQ$1:$AR$7,2,1) -> Evening | AK30: =IF(Orders[[#This Row],[rain_mode]]=0,"Sunny","Rainy") -> Sunny
A31: 172765721740638 | B31: TRUE | C31: MDM150 | D31: [{"id":"24ecd13d-e27f-4858-9c2a-bdc2b708cce4","super_type":"SUPERTYPE_UNSPECIFIED","total_offer_discount":150,"discount_share":{"swiggy_discount":75,"store_discount":75,"alliance_discount":0},"discount_type":"FLAT","description":"Flat ₹150 off","fixed_charges":{"gp":{"id":"","final_price":0}}}] | E31: 2024-04-22 19:58:41 | F31: 2024-04-22 19:59:12 | G31: 21191609 | H31: Delivered | I31: SUSHIL MANDAL | J31: 17036 | K31: Leon's - Burgers & Wings (Leon Grill) | L31: No.17, Ground Floor, 18th Cross Road, 3rd Sector, HSR Layout, Bangalore. | M31: HSR Layout | N31: Bangalore | O31: 1703 | P31: 724 | Q31: 724 | R31: 724 | S31: 797.57 | T31: 35 | U31: 0 | V31: 12.91181131,77.64374963 | W31: 1.6 | X31: MDM150 | Y31: UPICollect | Z31: HSR Layout | AA31: FALSE | AB31: 0 | AC31: =IF(X31="","No Coupon Applied",X31) -> MDM150 | AD31: =VLOOKUP(K31,'restaurant name correction'!$A$1:$B$44,2,0) -> Leon's | AE31: =VLOOKUP(Z31,restaurant_area_correction!$A$1:$B$18,2,0) -> HSR | AF31: =VALUE(IFERROR(MID(D31,FIND(":",D31,FIND("total_offer_discount",D31))+1,FIND(",",D31,FIND("total_offer_discount",D31)) - FIND(":",D31,FIND("total_offer_discount",D31))-1),0)) -> 150 | AG31: =DATEVALUE(E31) -> 45404 | AH31: =TIMEVALUE(E31) -> 0.83241898 | AI31: =TEXT(AG31,"dddd") -> Monday | AJ31: =VLOOKUP(HOUR(Orders[[#This Row],[Time]]),$AQ$1:$AR$7,2,1) -> Evening | AK31: =IF(Orders[[#This Row],[rain_mode]]=0,"Sunny","Rainy") -> Sunny
A32: 172415621290914 | B32: TRUE | C32: MDM150 | D32: [{"id":"8cdbbc6c-7669-489e-b255-421d322ec80f","super_type":"SUPERTYPE_UNSPECIFIED","total_offer_discount":150,"discount_share":{"swiggy_discount":75,"store_discount":75,"alliance_discount":0},"discount_type":"FLAT","description":"Flat ₹150 off","fixed_charges":{"gp":{"id":"","final_price":0}}}] | E32: 2024-04-18 18:43:41 | F32: 2024-04-18 18:44:05 | G32: 21191609 | H32: Delivered | I32: Kundan | J32: 17036 | K32: Leon's - Burgers & Wings (Leon Grill) | L32: No.17, Ground Floor, 18th Cross Road, 3rd Sector, HSR Layout, Bangalore. | M32: HSR Layout | N32: Bangalore | O32: 1726 | P32: 252 | Q32: 252 | R32: 252 | S32: 349 | T32: 31 | U32: 0 | V32: 12.91181131,77.64374963 | W32: 0.9 | X32: MDM150 | Y32: UPICollect | Z32: HSR Layout | AA32: TRUE | AB32: 0 | AC32: =IF(X32="","No Coupon Applied",X32) -> MDM150 | AD32: =VLOOKUP(K32,'restaurant name correction'!$A$1:$B$44,2,0) -> Leon's | AE32: =VLOOKUP(Z32,restaurant_area_correction!$A$1:$B$18,2,0) -> HSR | AF32: =VALUE(IFERROR(MID(D32,FIND(":",D32,FIND("total_offer_discount",D32))+1,FIND(",",D32,FIND("total_offer_discount",D32)) - FIND(":",D32,FIND("total_offer_discount",D32))-1),0)) -> 150 | AG32: =DATEVALUE(E32) -> 45400 | AH32: =TIMEVALUE(E32) -> 0.78033565 | AI32: =TEXT(AG32,"dddd") -> Thursday | AJ32: =VLOOKUP(HOUR(Orders[[#This Row],[Time]]),$AQ$1:$AR$7,2,1) -> Evening | AK32: =IF(Orders[[#This Row],[rain_mode]]=0,"Sunny","Rainy") -> Sunny
A33: 171120236353593 | B33: TRUE | C33: MDM150 | D33: [{"id":"8cdbbc6c-7669-489e-b255-421d322ec80f","super_type":"SUPERTYPE_UNSPECIFIED","total_offer_discount":150,"discount_share":{"swiggy_discount":75,"store_discount":75,"alliance_discount":0},"discount_type":"FLAT","description":"Flat ₹150 off","fixed_charges":{"gp":{"id":"","final_price":0}}}] | E33: 2024-04-03 18:53:56 | F33: 2024-04-03 18:54:20 | G33: 21191609 | H33: Delivered | I33: chandan K | J33: 17036 | K33: Leon's - Burgers & Wings (Leon Grill) | L33: No.17, Ground Floor, 18th Cross Road, 3rd Sector, HSR Layout, Bangalore. | M33: HSR Layout | N33: Bangalore | O33: 836 | P33: 252 | Q33: 252 | R33: 252 | S33: 349 | T33: 29 | U33: 0 | V33: 12.91181131,77.64374963 | W33: 0.2 | X33: MDM150 | Y33: UPICollect | Z33: HSR Layout | AA33: TRUE | AB33: 0 | AC33: =IF(X33="","No Coupon Applied",X33) -> MDM150 | AD33: =VLOOKUP(K33,'restaurant name correction'!$A$1:$B$44,2,0) -> Leon's | AE33: =VLOOKUP(Z33,restaurant_area_correction!$A$1:$B$18,2,0) -> HSR | AF33: =VALUE(IFERROR(MID(D33,FIND(":",D33,FIND("total_offer_discount",D33))+1,FIND(",",D33,FIND("total_offer_discount",D33)) - FIND(":",D33,FIND("total_offer_discount",D33))-1),0)) -> 150 | AG33: =DATEVALUE(E33) -> 45385 | AH33: =TIMEVALUE(E33) -> 0.7874537 | AI33: =TEXT(AG33,"dddd") -> Wednesday | AJ33: =VLOOKUP(HOUR(Orders[[#This Row],[Time]]),$AQ$1:$AR$7,2,1) -> Evening | AK33: =IF(Orders[[#This Row],[rain_mode]]=0,"Sunny","Rainy") -> Sunny
A34: 170949181342493 | B34: TRUE | C34: MDM150 | D34: [{"id":"8cdbbc6c-7669-489e-b255-421d322ec80f","super_type":"SUPERTYPE_UNSPECIFIED","total_offer_discount":150,"discount_share":{"swiggy_discount":75,"store_discount":75,"alliance_discount":0},"discount_type":"FLAT","description":"Flat ₹150 off","fixed_charges":{"gp":{"id":"","final_price":0}}}] | E34: 2024-04-01 19:23:01 | F34: 2024-04-01 19:23:06 | G34: 21191609 | H34: Delivered | I34: Noor Azam | J34: 17036 | K34: Leon's - Burgers & Wings (Leon Grill) | L34: No.17, Ground Floor, 18th Cross Road, 3rd Sector, HSR Layout, Bangalore. | M34: HSR Layout | N34: Bangalore | O34: 2224 | P34: 252 | Q34: 252 | R34: 252 | S34: 349 | T34: 34 | U34: 0 | V34: 12.91181131,77.64374963 | W34: 1.6 | X34: MDM150 | Y34: Cash | Z34: HSR Layout | AA34: FALSE | AB34: 0 | AC34: =IF(X34="","No Coupon Applied",X34) -> MDM150 | AD34: =VLOOKUP(K34,'restaurant name correction'!$A$1:$B$44,2,0) -> Leon's | AE34: =VLOOKUP(Z34,restaurant_area_correction!$A$1:$B$18,2,0) -> HSR | AF34: =VALUE(IFERROR(MID(D34,FIND(":",D34,FIND("total_offer_discount",D34))+1,FIND(",",D34,FIND("total_offer_discount",D34)) - FIND(":",D34,FIND("total_offer_discount",D34))-1),0)) -> 150 | AG34: =DATEVALUE(E34) -> 45383 | AH34: =TIMEVALUE(E34) -> 0.80765046 | AI34: =TEXT(AG34,"dddd") -> Monday | AJ34: =VLOOKUP(HOUR(Orders[[#This Row],[Time]]),$AQ$1:$AR$7,2,1) -> Evening | AK34: =IF(Orders[[#This Row],[rain_mode]]=0,"Sunny","Rainy") -> Sunny
A35: 170849767634192 | B35: TRUE | C35: MDM150 | D35: [{"id":"8cdbbc6c-7669-489e-b255-421d322ec80f","super_type":"SUPERTYPE_UNSPECIFIED","total_offer_discount":150,"discount_share":{"swiggy_discount":75,"store_discount":75,"alliance_discount":0},"discount_type":"FLAT","description":"Flat ₹150 off","fixed_charges":{"gp":{"id":"","final_price":0}}}] | E35: 2024-03-31 15:46:07 | F35: 2024-03-31 15:46:25 | G35: 21191609 | H35: Delivered | I35: Bharath R | J35: 17036 | K35: Leon's - Burgers & Wings (Leon Grill) | L35: No.17, Ground Floor, 18th Cross Road, 3rd Sector, HSR Layout, Bangalore. | M35: HSR Layout | N35: Bangalore | O35: 854 | P35: 252 | Q35: 252 | R35: 252 | S35: 349 | T35: 30 | U35: 0 | V35: 12.91181131,77.64374963 | W35: 1.6 | X35: MDM150 | Y35: UPICollect | Z35: HSR Layout | AA35: TRUE | AB35: 0 | AC35: =IF(X35="","No Coupon Applied",X35) -> MDM150 | AD35: =VLOOKUP(K35,'restaurant name correction'!$A$1:$B$44,2,0) -> Leon's | AE35: =VLOOKUP(Z35,restaurant_area_correction!$A$1:$B$18,2,0) -> HSR | AF35: =VALUE(IFERROR(MID(D35,FIND(":",D35,FIND("total_offer_discount",D35))+1,FIND(",",D35,FIND("total_offer_discount",D35)) - FIND(":",D35,FIND("total_offer_discount",D35))-1),0)) -> 150 | AG35: =DATEVALUE(E35) -> 45382 | AH35: =TIMEVALUE(E35) -> 0.65702546 | AI35: =TEXT(AG35,"dddd") -> Sunday | AJ35: =VLOOKUP(HOUR(Orders[[#This Row],[Time]]),$AQ$1:$AR$7,2,1) -> Afternoon | AK35: =IF(Orders[[#This Row],[rain_mode]]=0,"Sunny","Rainy") -> Sunny
A36: 170326417874188 | B36: TRUE | C36: SWIGGYIT | D36: [{"id":"16ef3f62-96d1-48fa-977b-3851da22b190","super_type":"SUPERTYPE_UNSPECIFIED","total_offer_discount":80,"discount_share":{"swiggy_discount":20,"store_discount":60,"alliance_discount":0},"discount_type":"PERCENTAGE","description":"40% off","fixed_charges":{"gp":{"id":"","final_price":0}}}] | E36: 2024-03-25 14:23:37 | F36: 2024-03-25 14:23:54 | G36: 21191609 | H36: Delivered | I36: MAHESH BABU | J36: 2675 | K36: Subway | L36: 36, 3rd Store, 7th Sector, 14th main, HSR Layout | M36: 7th Sector | N36: Bangalore | O36: 779 | P36: 252 | Q36: 252 | R36: 252 | S36: 300 | T36: 32 | U36: 0 | V36: 12.9118135,77.637958 | W36: 0.6 | X36: SWIGGYIT | Y36: UPICollect | Z36: Hsr Layout | AA36: TRUE | AB36: 0 | AC36: =IF(X36="","No Coupon Applied",X36) -> SWIGGYIT | AD36: =VLOOKUP(K36,'restaurant name correction'!$A$1:$B$44,2,0) -> Subway | AE36: =VLOOKUP(Z36,restaurant_area_correction!$A$1:$B$18,2,0) -> HSR | AF36: =VALUE(IFERROR(MID(D36,FIND(":",D36,FIND("total_offer_discount",D36))+1,FIND(",",D36,FIND("total_offer_discount",D36)) - FIND(":",D36,FIND("total_offer_discount",D36))-1),0)) -> 80 | AG36: =DATEVALUE(E36) -> 45376 | AH36: =TIMEVALUE(E36) -> 0.5997338 | AI36: =TEXT(AG36,"dddd") -> Monday | AJ36: =VLOOKUP(HOUR(Orders[[#This Row],[Time]]),$AQ$1:$AR$7,2,1) -> Afternoon | AK36: =IF(Orders[[#This Row],[rain_mode]]=0,"Sunny","Rainy") -> Sunny
A37: 169997934599848 | B37: TRUE | C37: FLATDEAL | D37: [{"id":"20f94987-8858-4c7d-bf7b-c2ff8a327fa8","super_type":"SUPERTYPE_UNSPECIFIED","total_offer_discount":99.99,"discount_share":{"swiggy_discount":0,"store_discount":99.99,"alliance_discount":0},"discount_type":"FLAT","description":"FLAT100 off","fixed_charges":{"gp":{"id":"","final_price":0}}}] | E37: 2024-03-21 19:08:54 | F37: 2024-03-21 19:09:08 | G37: 21191609 | H37: Delivered | I37: Kumar P | J37: 2675 | K37: Subway | L37: 36, 3rd Store, 7th Sector, 14th main, HSR Layout | M37: 7th Sector | N37: Bangalore | O37: 2901 | P37: 596 | Q37: 596 | R37: 596 | S37: 649 | T37: 34 | U37: 0 | V37: 12.9118135,77.637958 | W37: 1.9 | X37: FLATDEAL | Y37: UPICollect | Z37: Hsr Layout | AA37: FALSE | AB37: 0 | AC37: =IF(X37="","No Coupon Applied",X37) -> FLATDEAL | AD37: =VLOOKUP(K37,'restaurant name correction'!$A$1:$B$44,2,0) -> Subway | AE37: =VLOOKUP(Z37,restaurant_area_correction!$A$1:$B$18,2,0) -> HSR | AF37: =VALUE(IFERROR(MID(D37,FIND(":",D37,FIND("total_offer_discount",D37))+1,FIND(",",D37,FIND("total_offer_discount",D37)) - FIND(":",D37,FIND("total_offer_discount",D37))-1),0)) -> 99.99 | AG37: =DATEVALUE(E37) -> 45372 | AH37: =TIMEVALUE(E37) -> 0.79784722 | AI37: =TEXT(AG37,"dddd") -> Thursday | AJ37: =VLOOKUP(HOUR(Orders[[#This Row],[Time]]),$AQ$1:$AR$7,2,1) -> Evening | AK37: =IF(Orders[[#This Row],[rain_mode]]=0,"Sunny","Rainy") -> Sunny
A38: 169054716176265 | B38: TRUE | C38: SWIGGYIT | D38: [{"id":"e7373c56-9ba3-49f4-be3d-f75ecf92675e","super_type":"SUPERTYPE_UNSPECIFIED","total_offer_discount":80,"discount_share":{"swiggy_discount":20,"store_discount":60,"alliance_discount":0},"discount_type":"PERCENTAGE","description":"40% off","fixed_charges":{"gp":{"id":"","final_price":0}}}] | E38: 2024-03-10 21:08:36 | F38: 2024-03-10 21:09:03 | G38: 21191609 | H38: Delivered | I38: Subrath Panda | J38: 2675 | K38: Subway | L38: 36, 3rd Store, 7th Sector, 14th main, HSR Layout | M38: 7th Sector | N38: Bangalore | O38: 4130 | P38: 251 | Q38: 251 | R38: 251 | S38: 300 | T38: 57 | U38: 0 | V38: 12.9118135,77.637958 | W38: 1.9 | X38: SWIGGYIT | Y38: UPICollect | Z38: Hsr Layout | AA38: FALSE | AB38: 0 | AC38: =IF(X38="","No Coupon Applied",X38) -> SWIGGYIT | AD38: =VLOOKUP(K38,'restaurant name correction'!$A$1:$B$44,2,0) -> Subway | AE38: =VLOOKUP(Z38,restaurant_area_correction!$A$1:$B$18,2,0) -> HSR | AF38: =VALUE(IFERROR(MID(D38,FIND(":",D38,FIND("total_offer_discount",D38))+1,FIND(",",D38,FIND("total_offer_discount",D38)) - FIND(":",D38,FIND("total_offer_discount",D38))-1),0)) -> 80 | AG38: =DATEVALUE(E38) -> 45361 | AH38: =TIMEVALUE(E38) -> 0.88097222 | AI38: =TEXT(AG38,"dddd") -> Sunday | AJ38: =VLOOKUP(HOUR(Orders[[#This Row],[Time]]),$AQ$1:$AR$7,2,1) -> Night | AK38: =IF(Orders[[#This Row],[rain_mode]]=0,"Sunny","Rainy") -> Sunny
A39: 168959031219038 | B39: TRUE | C39: SWIGGYIT | D39: [{"id":"e7373c56-9ba3-49f4-be3d-f75ecf92675e","super_type":"SUPERTYPE_UNSPECIFIED","total_offer_discount":80,"discount_share":{"swiggy_discount":20,"store_discount":60,"alliance_discount":0},"discount_type":"PERCENTAGE","description":"40% off","fixed_charges":{"gp":{"id":"","final_price":0}}}] | E39: 2024-03-09 18:33:51 | F39: 2024-03-09 18:34:15 | G39: 21191609 | H39: Delivered | I39: Sreedhar V | J39: 2675 | K39: Subway | L39: 36, 3rd Store, 7th Sector, 14th main, HSR Layout | M39: 7th Sector | N39: Bangalore | O39: 864 | P39: 302 | Q39: 302 | R39: 302 | S39: 349 | T39: 32 | U39: 0 | V39: 12.9118135,77.637958 | W39: 1.9 | X39: SWIGGYIT | Y39: UPICollect | Z39: Hsr Layout | AA39: TRUE | AB39: 0 | AC39: =IF(X39="","No Coupon Applied",X39) -> SWIGGYIT | AD39: =VLOOKUP(K39,'restaurant name correction'!$A$1:$B$44,2,0) -> Subway | AE39: =VLOOKUP(Z39,restaurant_area_correction!$A$1:$B$18,2,0) -> HSR | AF39: =VALUE(IFERROR(MID(D39,FIND(":",D39,FIND("total_offer_discount",D39))+1,FIND(",",D39,FIND("total_offer_discount",D39)) - FIND(":",D39,FIND("total_offer_discount",D39))-1),0)) -> 80 | AG39: =DATEVALUE(E39) -> 45360 | AH39: =TIMEVALUE(E39) -> 0.77350694 | AI39: =TEXT(AG39,"dddd") -> Saturday | AJ39: =VLOOKUP(HOUR(Orders[[#This Row],[Time]]),$AQ$1:$AR$7,2,1) -> Evening | AK39: =IF(Orders[[#This Row],[rain_mode]]=0,"Sunny","Rainy") -> Sunny
A40: 168877172918547 | B40: FALSE | E40: 2024-03-08 19:49:32 | F40: 2024-03-08 19:49:59 | G40: 21191609 | H40: Delivered | I40: BIRENDRA DHAMI | J40: 464830 | K40: Bowl Soul | L40: No 526/A,Ganesh Complex,Ground floor,18th Main Road,HSR 3rd sector,Bangalore:560102 | M40: 3rd Sector | N40: Bangalore | O40: 2660 | P40: 154 | Q40: 154 | R40: 154 | S40: 249 | T40: 36 | U40: 0 | V40: 12.9054065,77.64410799999996 | W40: 1.8 | Y40: UPICollect | Z40: HSR Layout | AA40: FALSE | AB40: 0 | AC40: =IF(X40="","No Coupon Applied",X40) -> No Coupon Applied | AD40: =VLOOKUP(K40,'restaurant name correction'!$A$1:$B$44,2,0) -> Bowl Soul | AE40: =VLOOKUP(Z40,restaurant_area_correction!$A$1:$B$18,2,0) -> HSR | AF40: =VALUE(IFERROR(MID(D40,FIND(":",D40,FIND("total_offer_discount",D40))+1,FIND(",",D40,FIND("total_offer_discount",D40)) - FIND(":",D40,FIND("total_offer_discount",D40))-1),0)) -> 0 | AG40: =DATEVALUE(E40) -> 45359 | AH40: =TIMEVALUE(E40) -> 0.82606481 | AI40: =TEXT(AG40,"dddd") -> Friday | AJ40: =VLOOKUP(HOUR(Orders[[#This Row],[Time]]),$AQ$1:$AR$7,2,1) -> Evening | AK40: =IF(Orders[[#This Row],[rain_mode]]=0,"Sunny","Rainy") -> Sunny
...

Sheet Swiggy Order Items
A1: order_id | B1: order_items.name | C1: order_items.is_veg | D1: order_items.quantity | E1: Category
A2: 175244332362622 | B2: Michel (Chicken & Mozza Sandwich) | C2: 0 | D2: 1 | E2: =IF(C2=0,"Non_Veg","Veg") -> Non_Veg
A3: 175167017704058 | B3: Supreme Boneless Chicken Biryani | C3: 0 | D3: 1 | E3: =IF(C3=0,"Non_Veg","Veg") -> Non_Veg
A4: 175167017704058 | B4: Mutton Bone Soup | C4: 0 | D4: 1 | E4: =IF(C4=0,"Non_Veg","Veg") -> Non_Veg
A5: 175017114796029 | B5: Mississippi Mud Pie | C5: 0 | D5: 1 | E5: =IF(C5=0,"Non_Veg","Veg") -> Non_Veg
A6: 175017114796029 | B6: Apple Crumble Pie | C6: 1 | D6: 1 | E6: =IF(C6=0,"Non_Veg","Veg") -> Veg
A7: 174973046023416 | B7: Dark Chocolate Smoothie Bowl. | C7: 1 | D7: 1 | E7: =IF(C7=0,"Non_Veg","Veg") -> Veg
A8: 174973046023416 | B8: Banana Peanutbutter Overnight Oats [350kcals][20gm protein] | C8: 1 | D8: 1 | E8: =IF(C8=0,"Non_Veg","Veg") -> Veg
A9: 174906705849277 | B9: Chicken Kheema Lasagne | C9: 0 | D9: 1 | E9: =IF(C9=0,"Non_Veg","Veg") -> Non_Veg
A10: 174906705849277 | B10: Corn & Pepper Lasagne | C10: 1 | D10: 1 | E10: =IF(C10=0,"Non_Veg","Veg") -> Veg
A11: 174329455765789 | B11: Veg. Ramyun | C11: 1 | D11: 1 | E11: =IF(C11=0,"Non_Veg","Veg") -> Veg
A12: 174329455765789 | B12: Chicken Katsu Ramyun | C12: 0 | D12: 1 | E12: =IF(C12=0,"Non_Veg","Veg") -> Non_Veg
A13: 174318296922309 | B13: Onion Rings | C13: 1 | D13: 1 | E13: =IF(C13=0,"Non_Veg","Veg") -> Veg
... A171: 171863054117 | B171: Open Butter Masala Dosa | C171: 1 | D171: 1 | E171: =IF(C171=0,"Non_Veg","Veg") -> Veg

Sheet restaurant name correction
A1: restaurant_name | B1: restaurant_name_updated
A2: Paris Panini - Gourmet Sandwiches & Wraps | B2: =IFERROR(LEFT(A2,FIND("-",A2)-1),A2) -> Paris Panini
A3: Nandhana Palace | B3: =IFERROR(LEFT(A3,FIND("-",A3)-1),A3) -> Nandhana Palace
A4: The Ganache Factory - Cakes & Desserts | B4: =IFERROR(LEFT(A4,FIND("-",A4)-1),A4) -> The Ganache Factory
A5: Rasayan | B5: =IFERROR(LEFT(A5,FIND("-",A5)-1),A5) -> Rasayan
A6: Firangi Bake | B6: =IFERROR(LEFT(A6,FIND("-",A6)-1),A6) -> Firangi Bake
A7: Daily Sushi | B7: =IFERROR(LEFT(A7,FIND("-",A7)-1),A7) -> Daily Sushi
A8: Naalnaad Mane | B8: =IFERROR(LEFT(A8,FIND("-",A8)-1),A8) -> Naalnaad Mane
A9: Theobroma | B9: =IFERROR(LEFT(A9,FIND("-",A9)-1),A9) -> Theobroma
A10: Love And Crumble | B10: =IFERROR(LEFT(A10,FIND("-",A10)-1),A10) -> Love And Crumble
A11: Homely | B11: =IFERROR(LEFT(A11,FIND("-",A11)-1),A11) -> Homely
A12: Chowman | B12: =IFERROR(LEFT(A12,FIND("-",A12)-1),A12) -> Chowman
A13: Frozen Bottle - Milkshakes, Desserts And Ice Cream | B13: =IFERROR(LEFT(A13,FIND("-",A13)-1),A13) -> Frozen Bottle
... A44: Table for Tous | B44: =IFERROR(LEFT(A44,FIND("-",A44)-1),A44) -> Table for Tous

Sheet restaurant_area_correction
A1: restaurant_area_name | B1: restaurant_area_name_updated
A2: JP Nagar | B2: JP Nagar
A3: Jayanagar | B3: Jayanagar
A4: BTM 2nd Stage | B4: BTM
A5: BTM 1st Stage | B5: BTM
A6: Arekere | B6: Arekere
A7: HSR Layout | B7: HSR
A8: Malleshwaram | B8: Malleshwaram
A9: Bellandur | B9: Bellandur
A10: Bellandur Sarjapur | B10: Bellandur
A11: Koramangala | B11: Koramangala
A12: Yelahanka | B12: Yelahanka
... A18: Indiranagar | B18: Indiranagar

Sheet Data Prep
A1: Total Spend | B1: Sum of net_total | G1: Total Savings | H1: Sum of Discount | I1: Sum of free_delivery_discount_hit
B2: 25567 | H2: 4083.88 | I2: 2626 | J2: =GETPIVOTDATA("Sum of Discount",$H$1)+GETPIVOTDATA("Sum of free_delivery_discount_hit",$H$1) -> 6709.88
